<?xml version="1.0" ?>
<sdf version="1.7">
  <model name="FiveBar">
    <pose>0 0 0.26  0 0 0</pose>
    <self_collide>false</self_collide>
    <link name="base">
      <pose>0 0 0.0  0 0 0.0</pose>
      <inertial>
        <pose>0 0 -0.5  0 0 0</pose>
        <mass>10.0</mass>
        <inertia>
          <ixx>1e-3</ixx>
          <iyy>1e-3</iyy>
          <izz>1e-3</izz>
          <ixy>0.0</ixy>
          <ixz>0.0</ixz>
          <iyz>0.0</iyz>
        </inertia>
      </inertial>
      <gravity>0</gravity>
      <visual name="baseVisual">
        <pose>0 0 0.0  0 0 3.141592653589793</pose>
        <geometry>
          <mesh>
            <uri>meshes/BASE_Assembly.stl</uri>
            <scale>0.001 0.001 0.001 </scale>
          </mesh>
        </geometry>
        <transparency>0.8</transparency>
      </visual>
    </link>
    <link name="upperArmLeft">
      <pose>0 0 0.0  0 0 0.0</pose>
      <inertial>
        <pose>-0.014 0 -0.07  0 0 0.0</pose>
        <mass>1.0</mass>
        <inertia>
          <ixx>1e-6</ixx>
          <iyy>1e-6</iyy>
          <izz>1e-6</izz>
          <ixy>0.0</ixy>
          <ixz>0.0</ixz>
          <iyz>0.0</iyz>
        </inertia>
      </inertial>
      <gravity>0</gravity>
      <visual name="upperArmLeftVisual">
        <pose>0 0 0.0  0 0 3.141592653589793</pose>
        <geometry>
          <mesh>
            <uri>meshes/Upper_Arm_1.stl</uri>
            <scale>0.001 0.001 0.001 </scale>
          </mesh>
        </geometry>
      </visual>
    </link>
    <link name="lowerArmLeft">
      <pose>0 0 0.0  0 0 0.0</pose>
      <inertial>
        <pose>0.09 0.06796322535 -0.1 0 0 0.0</pose>
        <mass>0.1</mass>
        <inertia>
          <ixx>1e-6</ixx>
          <iyy>1e-6</iyy>
          <izz>1e-6</izz>
          <ixy>0.0</ixy>
          <ixz>0.0</ixz>
          <iyz>0.0</iyz>
        </inertia>
      </inertial>
      <gravity>0</gravity>
      <visual name="lowerArmLeftVisual">
        <pose>0 0 0.0  0 0 3.141592653589793</pose>
        <geometry>
          <mesh>
            <uri>meshes/Lower_Arm.stl</uri>
            <scale>0.001 0.001 0.001 </scale>
          </mesh>
        </geometry>
      </visual>
    </link>
    <link name="upperArmRight">
      <pose>0 0 0.0  0 0 0.0</pose>
      <inertial>
        <pose>0.104 0 -0.07 0 0 0</pose>
        <mass>1.0</mass>
        <inertia>
          <ixx>1e-6</ixx>
          <iyy>1e-6</iyy>
          <izz>1e-6</izz>
          <ixy>0.0</ixy>
          <ixz>0.0</ixz>
          <iyz>0.0</iyz>
        </inertia>
      </inertial>
      <gravity>0</gravity>
      <visual name="upperArmRightVisual">
        <pose>0 0 0.0  0 0 3.141592653589793</pose>
        <geometry>
          <mesh>
            <uri>meshes/Upper_Arm_2.stl</uri>
            <scale>0.001 0.001 0.001 </scale>
          </mesh>
        </geometry>
      </visual>
    </link>
    <link name="lowerArmRight">
      <pose>0 0 0.0  0 0 0.0</pose>
      <inertial>
        <pose>0.09 0.06796322535 -0.1 0 0 0.0</pose>
        <mass>0.1</mass>
        <inertia>
          <ixx>1e-6</ixx>
          <iyy>1e-6</iyy>
          <izz>1e-6</izz>
          <ixy>0.0</ixy>
          <ixz>0.0</ixz>
          <iyz>0.0</iyz>
        </inertia>
      </inertial>
      <gravity>0</gravity>
      <visual name="lowerArmRightVisual">
        <pose>0 0 0.0  0 0 3.141592653589793</pose>
        <geometry>
          <mesh>
            <uri>meshes/Z_Axis_Assembly.stl</uri>
            <scale>0.001 0.001 0.001 </scale>
          </mesh>
        </geometry>
      </visual>
    </link>
    <link name="endEffector">
      <pose>0.09 0.06796322535 -0.1 0 0 0.0</pose>
      <inertial>
        <pose>0 0 0.0  0 0 0.0</pose>
        <mass>0.3</mass>
        <inertia>
          <ixx>1e-6</ixx>
          <iyy>1e-6</iyy>
          <izz>1e-6</izz>
          <ixy>0.0</ixy>
          <ixz>0.0</ixz>
          <iyz>0.0</iyz>
        </inertia>
      </inertial>
      <gravity>0</gravity>
    </link>
    <joint name="fixBase" type="fixed">
      <pose>0 0 0 0 0 0</pose>
      <parent>world</parent>
      <child>base</child>
    </joint>
    <joint name="A11" type="revolute">
      <pose>-0.059 0 -0.07 0 0 0</pose>
      <parent>world</parent>
      <child>upperArmLeft</child>
      <axis>
        <xyz>0 0 1</xyz>
      </axis>
    </joint>
    <joint name="A21" type="revolute">
      <pose>0.059 0 -0.07 0 0 0</pose>
      <parent>world</parent>
      <child>upperArmRight</child>
      <axis>
        <xyz>0 0 1</xyz>
      </axis>
    </joint>
    <joint name="A12" type="revolute">
      <pose>0.031 0 -0.07 0 0 0.0</pose>
      <parent>upperArmLeft</parent>
      <child>lowerArmLeft</child>
      <axis>
        <xyz>0 0 1</xyz>
      </axis>
    </joint>
    <joint name="A22" type="revolute">
      <pose>0.149 0 -0.07 0 0 0.0</pose>
      <parent>upperArmRight</parent>
      <child>lowerArmRight</child>
      <axis>
        <xyz>0 0 1</xyz>
      </axis>
    </joint>
    <joint name="A13" type="revolute">
      <pose>0.09 0.06796322535 -0.1 0 0 0.0</pose>
      <parent>lowerArmLeft</parent>
      <child>lowerArmRight</child>
      <axis>
        <xyz>0 0 1</xyz>
      </axis>
    </joint>
    <joint name="fixEndEffector" type="fixed">
      <pose>0.09 0.06796322535 -0.1 0 0 0.0</pose>
      <parent>lowerArmLeft</parent>
      <child>endEffector</child>
    </joint>
    <plugin name="gazebo_ros_cosimulation" filename="libgazebo_ros_cosimulation.so">
    </plugin>
  </model>
</sdf>
